INFO - 2021-08-31 19:26:56,078 - new_apply_order.py[line:518]: 开始第 kencash【1】次进件……
INFO - 2021-08-31 19:26:56,079 - new_apply_order.py[line:79]: ======【ke测试环境】生成手机号：730409216 ======
INFO - 2021-08-31 19:26:56,457 - new_apply_order.py[line:86]: 730409216 检测用户存在成功！
INFO - 2021-08-31 19:26:56,500 - new_apply_order.py[line:93]: 730409216 短信发送成功！
INFO - 2021-08-31 19:26:56,542 - new_apply_order.py[line:103]: 730409216 注册成功！
INFO - 2021-08-31 19:26:56,588 - new_apply_order.py[line:113]: 730409216 登录短信发送成功！
INFO - 2021-08-31 19:26:56,634 - new_apply_order.py[line:121]: userId=6204055652588593152,mobile=730409216,token=fce2126f8188d24fcb5e1050a89f33d9 登录成功
INFO - 2021-08-31 19:26:57,303 - new_apply_order.py[line:172]: 个人信息提交成功！
INFO - 2021-08-31 19:26:57,353 - new_apply_order.py[line:188]: 联系人信息提交成功！
INFO - 2021-08-31 19:26:57,770 - new_apply_order.py[line:198]: 创建预审订单成功！
INFO - 2021-08-31 19:26:57,787 - new_apply_order.py[line:206]: 预审状态修改为通过,更新条数 1
INFO - 2021-08-31 19:26:57,802 - new_apply_order.py[line:209]: 更新初始额度！更新条数 1
INFO - 2021-08-31 19:26:58,056 - new_apply_order.py[line:221]: 活体图片上传成功！回写配置文件global_param.mp4_url
INFO - 2021-08-31 19:26:58,109 - new_apply_order.py[line:230]: 视频认证通过！
INFO - 2021-08-31 19:26:58,400 - new_apply_order.py[line:309]: 绑卡成功！
INFO - 2021-08-31 19:26:58,585 - new_apply_order.py[line:317]: 进件成功！执行sql将订单改为风控中……
INFO - 2021-08-31 19:26:59,622 - new_apply_order.py[line:323]: 订单表更新1条，信审更新1条
INFO - 2021-08-31 19:26:59,968 - new_apply_order.py[line:332]: 查询loan_order_id成功！
INFO - 2021-08-31 19:27:00,034 - new_apply_order.py[line:343]: 订单回调复审通过成功！
INFO - 2021-08-31 19:27:00,831 - new_apply_order.py[line:359]: 获取token成功！token=bearer fce2813d-ef13-467f-87e4-fa50eb220394！
INFO - 2021-08-31 19:27:01,174 - new_apply_order.py[line:332]: 查询loan_order_id成功！
INFO - 2021-08-31 19:27:01,747 - new_apply_order.py[line:371]: 后台已触发放款成功！
ERROR - 2021-08-31 19:27:01,755 - new_apply_order.py[line:564]: HTTPConnectionPool(host='http', port=80): Max retries exceeded with url: //172.20.240.133:8066/xxl-job-admin/login (Caused by NewConnectionError('<urllib3.connection.HTTPConnection object at 0x7f8ccdadf070>: Failed to establish a new connection: [Errno 8] nodename nor servname provided, or not known'))
ERROR - 2021-08-31 19:27:01,780 - new_apply_order.py[line:565]: None
